<?xml version="1.0"?>
<robot name="robot">
  <link name="torso">
    <inertial>
      <origin rpy="0 0 0" xyz="0 0 1.5"/>
      <mass value="1"/>
      <inertia ixx="0.16666666666666666" ixy="0.0" ixz="0.0" iyy="0.16666666666666666" iyz="0.0" izz="0.16666666666666666"/>
    </inertial>
    <visual>
      <origin rpy="0 0 0" xyz="0 0 1.5"/>
      <geometry>
        <box size="1 1 1"/>
      </geometry>
      <material name="Cyan">
        <color rgba="0 1.0 1.0 1.0"/>
      </material>
    </visual>
    <collision>
      <origin rpy="0 0 0" xyz="0 0 1.5"/>
      <geometry>
        <box size="1 1 1"/>
      </geometry>
    </collision>
  </link>
  <link name="rightleg">
    <inertial>
      <origin rpy="0 0 0" xyz="0.5 0 -0.5"/>
      <mass value="1"/>
      <inertia ixx="0.16666666666666666" ixy="0.0" ixz="0.0" iyy="0.16666666666666666" iyz="0.0" izz="0.16666666666666666"/>
    </inertial>
    <visual>
      <origin rpy="0 0 0" xyz="0.5 0 -0.5"/>
      <geometry>
        <box size="1 1 1"/>
      </geometry>
      <material name="Cyan">
        <color rgba="0 1.0 1.0 1.0"/>
      </material>
    </visual>
    <collision>
      <origin rpy="0 0 0" xyz="0.5 0 -0.5"/>
      <geometry>
        <box size="1 1 1"/>
      </geometry>
    </collision>
  </link>
  <link name="leftleg">
    <inertial>
      <origin rpy="0 0 0" xyz="-0.5 0 -0.5"/>
      <mass value="1"/>
      <inertia ixx="0.16666666666666666" ixy="0.0" ixz="0.0" iyy="0.16666666666666666" iyz="0.0" izz="0.16666666666666666"/>
    </inertial>
    <visual>
      <origin rpy="0 0 0" xyz="-0.5 0 -0.5"/>
      <geometry>
        <box size="1 1 1"/>
      </geometry>
      <material name="Cyan">
        <color rgba="0 1.0 1.0 1.0"/>
      </material>
    </visual>
    <collision>
      <origin rpy="0 0 0" xyz="-0.5 0 -0.5"/>
      <geometry>
        <box size="1 1 1"/>
      </geometry>
    </collision>
  </link>
  <joint name="torso_rightleg" type="revolute">
    <parent link="torso"/>
    <child link="rightleg"/>
    <origin rpy="0 0 0" xyz="0.5 0 1"/>
    <axis xyz="0 1 0"/>
    <limit effort="1.0" lower="-3.14159" upper="3.14159" velocity="1.0"/>
  </joint>
  <joint name="torso_leftleg" type="revolute">
    <parent link="torso"/>
    <child link="leftleg"/>
    <origin rpy="0 0 0" xyz="-0.5 0 1"/>
    <axis xyz="0 1 0"/>
    <limit effort="1.0" lower="-3.14159" upper="3.14159" velocity="1.0"/>
  </joint>
</robot>
